Workbook

Sheet Servers
A1: Meta | F1: A. General | S1: B. Access / Pricing | Z1: C. Capabilities (summary; details on sheet "Capabilities") | AA1: D. Server-Side Logic | AD1: E. Aggregated Evaluation | AI1: F. Documentation Analysis | AM1: Meta
A2: Server | B2: Status | C2: Analyst / method | D2: Analysis date | E2: Fields filled, % | F2: Endpoint (from CSV) | G2: Documentation (from CSV) | H2: Addressing (from CSV) | I2: Code repository link | J2: Documentation used (link) | K2: Open code = deployed server? | L2: MCP version (protocol) | M2: Commit hash | N2: Commit date | O2: Implementation language | P2: MCP SDK and version | Q2: Code public? | R2: License | S2: MCP server access: free / paid | T2: MCP server cost (how much) | U2: Linked software: open source / paid | V2: Linked software cost | W2: Pricing model (details) | X2: Other access restrictions (which) | Y2: Restrictions controlled by | Z2: Capabilities implemented (count) | AA2: Additional logic between LLM and software (governance) | AB2: Server structure | AC2: Structure: explanation | AD2: Number of actions (from sheet Actions) | AE2: Number of actions (manual / comment) | AF2: Tokens before first action | AG2: Token counting method | AH2: Actions a human can do but the agent cannot | AI2: Recommendations in docs not enforced by the server | AJ2: Governance promises (data, rights, reversibility, logging) | AK2: Promises to the user | AL2: Promises vs. server logic | AM2: Sources (links) | AN2: Notes / questions
A3: tavily | B3: Verified | C3: Manual analysis using Claude Opus 5.5 for verification and code analysis | D3: 2026-10-12; re-analysed 2026-10-15 (new commit in the repository) | E3: =((LEN(TRIM(I3))>0)*1+(LEN(TRIM(J3))>0)*1+(LEN(TRIM(K3))>0)*1+(LEN(TRIM(L3))>0)*1+(LEN(TRIM(M3))>0)*1+(LEN(TRIM(N3))>0)*1+(LEN(TRIM(O3))>0)*1+(LEN(TRIM(P3))>0)*1+(LEN(TRIM(Q3))>0)*1+(LEN(TRIM(R3))>0)*1+(LEN(TRIM(S3))>0)*1+(LEN(TRIM(T3))>0)*1+(LEN(TRIM(U3))>0)*1+(LEN(TRIM(V3))>0)*1+(LEN(TRIM(W3))>0)*1+(LEN(TRIM(X3))>0)*1+(LEN(TRIM(Y3))>0)*1+(LEN(TRIM(AA3))>0)*1+(LEN(TRIM(AB3))>0)*1+(LEN(TRIM(AC3))>0)*1+(LEN(TRIM(AE3))>0)*1+(LEN(TRIM(AF3))>0)*1+(LEN(TRIM(AG3))>0)*1+(LEN(TRIM(AH3))>0)*1+(LEN(TRIM(AI3))>0)*1+(LEN(TRIM(AJ3))>0)*1+(LEN(TRIM(AK3))>0)*1+(LEN(TRIM(AL3))>0)*1)/28 | F3: https://mcp.tavily.com/mcp | G3: https://docs.tavily.com/mcp | H3: global | I3: https://github.com/tavily-ai/tavily-mcp (local stdio version only; the remote server's code is not published) | J3: https://docs.tavily.com/documentation/mcp (the CSV link https://docs.tavily.com/mcp now serves the documentation MCP server, not a page) | K3: Partially | L3: SDK supports 2025-11-25 (latest), 2025-06-18, 2025-03-26, 2024-11-05, 2024-10-07; not 2026-07-28 | M3: 688b0f78d518d507cb31b94d9cc0e44c6eadd7c0 | N3: 2026-10-15 | O3: TypeScript (Node.js >= 20) | P3: @modelcontextprotocol/sdk 1.31.0 (low-level Server class) | Q3: Partially | R3: MIT (local version only) | S3: Freemium | T3: The MCP server itself is free (MIT code); you pay for the Tavily API calls it makes | U3: Paid | V3: Free: 1,000 credits/month; PAYG $0.008/credit; Project 4,000 cr./$30; Bootstrap 15,000/$100; Startup 38,000/$220; Growth 100,000/$500; Enterprise custom | W3: Credits. Search: basic/fast/ultra-fast = 1 credit, advanced = 2. Extract: 1 credit per 5 successful URLs (advanced 2). Map: 1 credit per 10 pages (with instructions 2). Crawl = Map + Extract. Research: mini 4-110, pro 15-250 credits per request. | X3: Keyless mode (no key): free, rate-limited, only Search and Extract; Crawl/Map/Research need a key. Rate limits: development key 100 req/min, production key 1,000/min; Crawl 100/min; Research 20/min. Production key only with a paid plan or PAYGO. With OAuth the key `mcp_auth_default` is used (personal before team), else `default`, else the first one. | Y3: Tavily (API side); the MCP server adds only research timeouts | Z3: =COUNTIFS(Capabilities!$A:$A,$A3,Capabilities!$C:$C,"Yes")+COUNTIFS(Capabilities!$A:$A,$A3,Capabilities!$C:$C,"Partially") | AA3: 1) DEFAULT_PARAMETERS set by the operator REPLACE the AI's search parameters (not only fill gaps), silently. 2) Parameter correction: country forces topic=general; dates remove time_range; empty values removed. 3) crawl hard-codes chunks_per_source=3. 4) crawl output truncated to the first 200 characters per page. 5) research: polling 2 s x1.5 up to 10 s, limit 5/15 min, automatic switch to streaming; incomplete report -> error. 6) X-Session-Id / X-Human-Id / X-Client-Source headers on every request (vendor analytics). 7) tavily_feedback tool instructs the agent to rate every result and send its final answer to Tavily. 8) Keyless limit responses return commercial options (x402 payment, sign-up, bonus credits for answering questions) as normal text. No permission checks, human confirmation or domain restrictions. | AB3: Standard | AC3: Flat: one process -> 6 tools, each a wrapper around one REST endpoint of api.tavily.com. No hierarchy, no sub-servers. | AD3: =COUNTIF(Actions!$A:$A,$A3) | AE3: 6 in the local code; 5 in the remote server documentation (without tavily_feedback) | AF3: ~3,300 | AG3: Length of the JSON tool descriptions / 4 characters per token (+-30 %, model-dependent); no server instructions | AH3: Search API parameters not exposed: include_answer, auto_parameters, chunks_per_source, include_domains_mode, language, filter_by_language, include_published_date, filter_by_published_date, include_usage, safe_search. Cannot change chunks_per_source in crawl (fixed 3). Cannot view credit usage, manage keys, plan or team (web dashboard only). Cannot get the full page text in crawl (only 200 characters). | AI3: Use an opaque user ID, not an e-mail ("prefer opaque identifiers ... over raw PII"). The official OpenAI example sets "require_approval": "never" (human confirmation off). The API key is suggested in the URL (?tavilyApiKey=...) without a risk warning. No recommendations on human confirmation. | AJ3: Human ID hashed with SHA-256 before storage, raw ID not stored. Privacy policy: Tavily may use parts of request data to improve future responses (legitimate interest; EU users can object by e-mail); queries may be passed to third-party search indexes (e.g. Google); data kept while the account exists; deletion on request. Nothing on logging of agent actions or reversibility. | AK3: "real-time web search", "seamless experience without requiring local installation"; identifiers help Tavily "better understand multi-step interactions and improve response quality" | AL3: Hashing of the human ID cannot be verified from the code (API side). The server forwards X-Human-Id only if it is set (consistent). | AM3: https://github.com/tavily-ai/tavily-mcp/tree/688b0f78d518d507cb31b94d9cc0e44c6eadd7c0 https://docs.tavily.com/documentation/mcp https://docs.tavily.com/documentation/api-credits https://docs.tavily.com/documentation/rate-limits https://docs.tavily.com/documentation/keyless https://docs.tavily.com/documentation/api-reference/endpoint/search https://www.tavily.com/privacy | AN3: The CSV endpoint is the remote server (closed code); the code analysis refers to the local version. Package version 0.2.23 in package.json, but the server reports 0.2.22. Last change to the server code: 08dfecd (2026-10-15).
A4: grafana | B4: Verified | C4: Manual analysis using Claude Opus 5.5 for verification and code analysis | D4: 2026-10-12; re-analysed 2026-10-23 (new commit in the repository) | E4: =((LEN(TRIM(I4))>0)*1+(LEN(TRIM(J4))>0)*1+(LEN(TRIM(K4))>0)*1+(LEN(TRIM(L4))>0)*1+(LEN(TRIM(M4))>0)*1+(LEN(TRIM(N4))>0)*1+(LEN(TRIM(O4))>0)*1+(LEN(TRIM(P4))>0)*1+(LEN(TRIM(Q4))>0)*1+(LEN(TRIM(R4))>0)*1+(LEN(TRIM(S4))>0)*1+(LEN(TRIM(T4))>0)*1+(LEN(TRIM(U4))>0)*1+(LEN(TRIM(V4))>0)*1+(LEN(TRIM(W4))>0)*1+(LEN(TRIM(X4))>0)*1+(LEN(TRIM(Y4))>0)*1+(LEN(TRIM(AA4))>0)*1+(LEN(TRIM(AB4))>0)*1+(LEN(TRIM(AC4))>0)*1+(LEN(TRIM(AE4))>0)*1+(LEN(TRIM(AF4))>0)*1+(LEN(TRIM(AG4))>0)*1+(LEN(TRIM(AH4))>0)*1+(LEN(TRIM(AI4))>0)*1+(LEN(TRIM(AJ4))>0)*1+(LEN(TRIM(AK4))>0)*1+(LEN(TRIM(AL4))>0)*1)/28 | F4: https://mcp.grafana.com/mcp | G4: https://grafana.com/docs/grafana/latest/developer-resources/mcp/ | H4: global | I4: https://github.com/grafana/mcp-grafana (open server; the cloud server at the CSV endpoint is not fully published) | J4: https://grafana.com/docs/grafana/latest/developer-resources/mcp/ (open server, from CSV); https://grafana.com/docs/grafana-cloud/ai-tools/mcp-servers/cloud-mcp/ (cloud server) | K4: Partially | L4: go-sdk v1.8.0 supports 2026-07-28 (latest, default), 2025-11-25, 2025-06-18, 2025-03-26, 2024-11-05 | M4: e97cd4479eb40d25bc8d466db1651c29ce0c783e | N4: 2026-10-23 | O4: Go (module github.com/grafana/mcp-grafana/v2, go 1.26.10) | P4: github.com/modelcontextprotocol/go-sdk v1.8.0 (official) | Q4: Partially | R4: Apache 2.0 (open server); cloud server closed | S4: Freemium | T4: Open server free. Cloud: each connected user counts as an "active AI user" of Grafana Assistant. Free plan: up to 3 active AI users/month (40M tokens each) + 25M tokens for service accounts, blocked above the limit. Pro: $20 per active AI user (40M tokens included), extra tokens $2 per 1M. Simple data queries consume no tokens, Assistant functions do. | U4: Open source + paid cloud | V4: Grafana OSS free; Grafana Cloud Free $0, Pro from $19/month + usage, Enterprise from $25,000/year | W4: Cloud MCP is billed via Grafana Assistant (active AI users + tokens); see server cost. Grafana Cloud itself: usage-based tiers. | X4: Grafana >= 9.0. Cloud: Grafana Cloud only, Assistant available on the stack, Assistant terms accepted; role "Assistant Cloud MCP User" (Editor+ by default); Write may need "Assistant Admin"; OAuth consent screen with Read / Query / Write levels (Write needs scope grafana:write). Rate limits not documented; default request timeout to Grafana 10 s. | Y4: Grafana administrator (RBAC), server operator (flags --enabled-tools, --disable-write, --disable-query ...), user (cloud OAuth consent screen) | Z4: =COUNTIFS(Capabilities!$A:$A,$A4,Capabilities!$C:$C,"Yes")+COUNTIFS(Capabilities!$A:$A,$A4,Capabilities!$C:$C,"Partially") | AA4: 1) Operator modes: --disable-write (removes writing tools; grafana_api_request GET-only), --disable-query, category toggles (12 categories off by default). 2) The server classifies query languages by danger (SQL and InfluxQL count as writing). 3) Server instructions change with the configuration. 4) Unknown arguments rejected with a list of valid names; automatic type coercion. 5) Loki cost limiter (--loki-guardrail-mode off|shadow|enforce: selector, 24 h range, 100 GiB scan; rejects with a rewrite hint; off by default). 6) Enforced Loki matchers (the AI can only narrow; fail closed; warns about bypasses). 7) Response size limits (Loki 10 lines default, max 100, +1 line to signal truncation); economical dashboard tools. 8) HTTP security: Host/Origin checks, no cross-domain redirects, URL whitelist. 9) Required RBAC permissions declared in _meta, checked by Grafana (403). 10) Metrics/tracing; arguments in spans only with a flag. No human confirmation (cloud: only the OAuth consent screen). | AB4: Standard | AC4: Flat but modular: 34 categories switched on/off by flags; no hierarchy of sub-servers. Cloud: Tempo tools are proxied from the MCP servers of Tempo data sources. A universal tool (grafana_api_request) covers the whole Grafana API. | AD4: =COUNTIF(Actions!$A:$A,$A4) | AE4: 119 tools in the open code, 79 enabled by default; several are multi-operation; grafana_api_request reaches any API endpoint. Cloud server: list in the docs incomplete (by category), without grafana_api_request, plus Assistant tools. | AF4: ~27,000 by default (79 tools ~26,600 + instructions ~460); ~40,000 with everything enabled | AG4: Length of the reconstructed tools/list JSON / 4 characters per token (+-30 %) | AH4: With grafana_api_request (default): almost nothing beyond the token's RBAC rights; the real boundary is RBAC. Without it (or in the cloud server): no tools to delete dashboards, folders or data sources, to manage users, teams, service accounts and roles (admin tools read only), organisation settings, remove/disable plugins, change resource permissions. Browser-only: visual panel editing, Explore UI (agent can only get a deeplink or a panel image). | AI4: Give the service account only the necessary permissions (Editor is "less restrictive"). Use --include-args-in-spans only outside production / without personal data. Do not expose the server without --server-auth-token; use TLS. For URL overrides deploy behind an authenticating proxy and restrict outbound network access. Disable bypasses (--disable-api, --disable-rendering, --disable-assistant) for Loki restrictions to work. Cloud: for read-only untick both Write and Query ("clearing only Write access still allows raw SQL"). No recommendations on human confirmation. | AJ4: Anonymous usage statistics ON by default (every 4 h: tools called, error counts, configuration; not arguments, queries, logs, credentials, instance URL; coarse region/network added from IP; opt-out --usage-stats=disabled or DO_NOT_TRACK=1). SQL: "credentials are never seen by the MCP server". Cloud: "Grafana doesn't train AI models on your PromQL, LogQL queries, investigation content, or prompt payload data"; LLM providers (Anthropic, Google Vertex AI, Amazon Bedrock) with zero retention; conversations kept 30/90/180 days (default 90); up to 30 days after deletion; employee access restricted and audited. Reversibility: dashboard versions exist, no one-command rollback; delete_annotation is "Permanently delete". | AK4: Feature list "for informational purposes only and does not represent a roadmap or commitment"; deeplinks "instead of relying on LLM URL guessing" | AL4: Statistics statements match the code (usagestats/), but on-by-default means data is sent without explicit consent. Loki restrictions are implemented and honestly documented together with their bypasses. | AM4: https://github.com/grafana/mcp-grafana/tree/e97cd4479eb40d25bc8d466db1651c29ce0c783e https://grafana.com/docs/grafana/latest/developer-resources/mcp/ https://grafana.com/docs/grafana-cloud/ai-tools/mcp-servers/cloud-mcp/ https://grafana.com/docs/grafana-cloud/ai-tools/mcp-servers/register-oauth-client https://grafana.com/pricing/ https://grafana.com/docs/grafana-cloud/platform/pricing-and-usage/assistant/ https://grafana.com/docs/grafana-cloud/platform/grafana-assistant/privacy-and-security/privacy/ https://grafana.com/docs/grafana/latest/developer-resources/mcp/anonymous-usage-statistics/ https://grafana.com/docs/grafana/latest/developer-resources/api-reference/http-api/ | AN4: The CSV endpoint is the cloud server (separate hosted product, not fully published); the code analysis refers to the open server. Latest release tag v2.1.1. Actions sheet: tool list generated from the appendix 02b (type from readOnlyHint of all variants; description = first sentence of the verbatim description).
A5: basic-memory | B5: Verified | C5: Manual analysis using Claude Opus 5.5 for verification and code analysis | D5: 2026-10-12; re-analysed 2026-10-23 (new commit in the repository) | E5: =((LEN(TRIM(I5))>0)*1+(LEN(TRIM(J5))>0)*1+(LEN(TRIM(K5))>0)*1+(LEN(TRIM(L5))>0)*1+(LEN(TRIM(M5))>0)*1+(LEN(TRIM(N5))>0)*1+(LEN(TRIM(O5))>0)*1+(LEN(TRIM(P5))>0)*1+(LEN(TRIM(Q5))>0)*1+(LEN(TRIM(R5))>0)*1+(LEN(TRIM(S5))>0)*1+(LEN(TRIM(T5))>0)*1+(LEN(TRIM(U5))>0)*1+(LEN(TRIM(V5))>0)*1+(LEN(TRIM(W5))>0)*1+(LEN(TRIM(X5))>0)*1+(LEN(TRIM(Y5))>0)*1+(LEN(TRIM(AA5))>0)*1+(LEN(TRIM(AB5))>0)*1+(LEN(TRIM(AC5))>0)*1+(LEN(TRIM(AE5))>0)*1+(LEN(TRIM(AF5))>0)*1+(LEN(TRIM(AG5))>0)*1+(LEN(TRIM(AH5))>0)*1+(LEN(TRIM(AI5))>0)*1+(LEN(TRIM(AJ5))>0)*1+(LEN(TRIM(AK5))>0)*1+(LEN(TRIM(AL5))>0)*1)/28 | F5: https://cloud.basicmemory.com/mcp | G5: https://docs.basicmemory.com/cloud/cloud-guide | H5: global | I5: https://github.com/basicmachines-co/basic-memory | J5: https://docs.basicmemory.com/cloud/cloud-guide (from CSV); https://docs.basicmemory.com/reference/mcp-tools-reference | K5: Partially | L5: Python SDK mcp 2.3.0: 2024-11-05, 2025-03-26, 2025-06-18, 2025-11-25 (initialize handshake) and 2026-07-28 (stateless); latest 2026-07-28 | M5: 9b47a7cd4784ca3a4df5d85437bdbd2db2dee587 | N5: 2026-10-23 | O5: Python >= 3.12 | P5: FastMCP 4.1.3 (on top of the official mcp 2.3.0) | Q5: Partially | R5: AGPL-3.0 (cloud parts partly closed) | S5: Freemium | T5: Local: free ("Free to run locally"). Cloud: active subscription required. Team $15 per seat/month ($13 from 10 seats, $12 from 20); Business $30 per seat/month; Agent Infrastructure custom; 7-day trial. | U5: Open source + paid cloud | V5: Program open source (AGPL-3.0); cloud subscription as above (README still describes the old "$15.00/mo ... One plan, no tiers" with OSS discount code BMFOSS) | W5: Per seat per month (Team / Business), Agent Infrastructure: credits / metered usage. Cloud built on WorkOS AuthKit, Neon Postgres, Tigris S3, Polar.sh. | X5: Cloud: subscription ("Active subscription required"). User settings in ~/.basic-memory/config.json: project deletion off by default (enable_project_delete=false), POSIX tools can be hidden, overwriting notes forbidden by default. Cloud: ZIP upload up to 100 MB; .env and similar files are not uploaded. | Y5: Basic Machines (subscription); user (local config) | Z5: =COUNTIFS(Capabilities!$A:$A,$A5,Capabilities!$C:$C,"Yes")+COUNTIFS(Capabilities!$A:$A,$A5,Capabilities!$C:$C,"Partially") | AA5: 1) Behaviour rules only in server instructions (check recent_activity before answering; offer to save and wait for agreement; "Do not create notes unprompted") - not enforced by code. 2) Overwrite protection: ALREADY_EXISTS unless overwrite=true. 3) Optimistic locking with expected_checksum (REVISION_CONFLICT). 4) Dangerous operations need explicit parameters: recursive=true for folder deletion; project deletion hidden unless enable_project_delete. 5) Project boundaries incl. symlinks (OUTSIDE_PROJECT). 6) Memory: past writes come back in future sessions; similar-notes hints after writing. 7) Built-in manual for the AI (memory://man). 8) Client-specific behaviour (search/fetch only for OpenAI). 9) Silent auto-update of CLI installs every 24 h. No permission checks locally, no protocol-level human confirmation, no rate limits. | AB5: Standard | AC5: Flat, one server; tool groups switched by FastMCP tags; transition period with old and new (bm_*) sets visible at the same time; local <-> cloud routing by project/workspace. | AD5: =COUNTIF(Actions!$A:$A,$A5) | AE5: 37 visible by default (39 registered, 2 project-deletion tools hidden; 2 more defined but not registered); about 15 actions that differ in meaning (old/new duplicates, OpenAI wrappers). Several tools contain multiple operations (bm_edit 7 commands, bm_project list/create/recent). | AF5: ~11,400 (tools + resources + prompts ~10,900, instructions ~520) | AG5: Length of the reconstructed description / 4 characters per token (+-30 %); about half is duplicate old tools | AH5: Import from ChatGPT, Claude, documents, memory.json (CLI only). Cloud: snapshots and restore, push/pull sync (bisync), ZIP upload, sharing, subscription, teams and workspaces (except list_workspaces). Database maintenance: reindex, prune, orphans, doctor, update. Delete a project unless the user enabled it. Cloud web app: comments and suggested edits (partly via review_note in the cloud MCP). | AI5: "Deletion is irreversible for active project storage"; "Back up any local files you need before running the destructive command". Agents should not write CriticMarkup directly. Pass workspace for a clean deletion of cloud data from a local session. No separate confirmation step before destructive actions is described. | AJ5: Local: "Notes and content never leave your device". Cloud: "We don't train AI models", encrypted at rest and in transit, servers in the USA, data kept 30 days after cancellation (backups up to 90 days), "We don't sell your data". CLI telemetry on by default (anonymous CLI -> cloud funnel events to Umami Cloud; no file contents, titles, IP, tool calls; opt-out BASIC_MEMORY_NO_PROMOS=1); Logfire off by default. Reversibility: "No lock-in ... Export to local Markdown any time"; cloud snapshots and point-in-time restore; no versions for local notes. Diagnostics read-only, secrets masked. | AK5: "Your AI never forgets again"; "Every tool is annotated with MCP behavior hints ... so agents can pick the right one without trial-and-error"; "Cancel anytime, your data stays yours" | AL5: Annotation promise kept (all tools annotated). "Do not create notes unprompted" exists only as text in the instructions; the code does not enforce it. "Notes never leave your device" consistent with the code when the cloud is off; CLI telemetry sends events only (analytics.py). | AM5: https://github.com/basicmachines-co/basic-memory/tree/9b47a7cd4784ca3a4df5d85437bdbd2db2dee587 https://docs.basicmemory.com/cloud/cloud-guide https://docs.basicmemory.com/reference/mcp-tools-reference https://docs.basicmemory.com/cloud/routing https://basicmemory.com/pricing https://basicmemory.com/privacy | AN5: The CSV endpoint is the cloud server; it has closed extras (review_note, open_basic_memory, review_mode, workspace). The code analysis refers to the open server. Actions sheet: generated from the appendix 03b (type from readOnlyHint; description = first sentence of the verbatim description).
A6: shapes | B6: Verified | C6: Manual analysis using Claude Opus 5.5 for verification and code analysis | D6: 2026-10-12 | E6: =((LEN(TRIM(I6))>0)*1+(LEN(TRIM(J6))>0)*1+(LEN(TRIM(K6))>0)*1+(LEN(TRIM(L6))>0)*1+(LEN(TRIM(M6))>0)*1+(LEN(TRIM(N6))>0)*1+(LEN(TRIM(O6))>0)*1+(LEN(TRIM(P6))>0)*1+(LEN(TRIM(Q6))>0)*1+(LEN(TRIM(R6))>0)*1+(LEN(TRIM(S6))>0)*1+(LEN(TRIM(T6))>0)*1+(LEN(TRIM(U6))>0)*1+(LEN(TRIM(V6))>0)*1+(LEN(TRIM(W6))>0)*1+(LEN(TRIM(X6))>0)*1+(LEN(TRIM(Y6))>0)*1+(LEN(TRIM(AA6))>0)*1+(LEN(TRIM(AB6))>0)*1+(LEN(TRIM(AC6))>0)*1+(LEN(TRIM(AE6))>0)*1+(LEN(TRIM(AF6))>0)*1+(LEN(TRIM(AG6))>0)*1+(LEN(TRIM(AH6))>0)*1+(LEN(TRIM(AI6))>0)*1+(LEN(TRIM(AJ6))>0)*1+(LEN(TRIM(AK6))>0)*1+(LEN(TRIM(AL6))>0)*1)/28 | F6: https://mcp.shapes.co/mcp | G6: https://shapes.co/mcp | H6: global | I6: Not published | J6: https://shapes.co/mcp (from CSV); https://mcp.shapes.co/ (technical page); https://claude.com/connectors/shapes | K6: Unknown | L6: Not published (requires sign-in) | M6: Not applicable (closed code) | N6: Documentation snapshot 2026-10-12 | O6: Not published | P6: Not published | Q6: No | R6: Proprietary | S6: Paid | T6: No separate price; only for existing Shapes customers ("Existing Shapes customers can connect directly"), others contact sales | U6: Paid | V6: Core $8 per seat/month, Plus $12 per seat/month (billed annually), minimum subscription (size not given); Surveys, Performance and Compensation modules priced on request | W6: Per-seat SaaS subscription; MCP not mentioned in the plan feature lists | X6: OAuth sign-in with each employee's own Shapes account; "Your existing Shapes permissions carry through to every Claude conversation"; the Claude connector is set up by the organisation's administrator. Rate limits not documented. | Y6: Customer's Shapes HR administrators (permissions); Shapes (subscription) | Z6: =COUNTIFS(Capabilities!$A:$A,$A6,Capabilities!$C:$C,"Yes")+COUNTIFS(Capabilities!$A:$A,$A6,Capabilities!$C:$C,"Partially") | AA6: According to the documentation (not verifiable): 1) Read-only at the level of the whole server - no writing tools at all. 2) User permissions carry over ("you can only access data you're authorized to see"), filtering on the Shapes side. 3) Aggregating tools compute statistics instead of returning raw records. 4) Separate "my" tools for the user's own data. Human confirmation, confidence scores, logging not described. | AB6: Standard | AC6: Flat set of tools (according to the documentation) | AD6: =COUNTIF(Actions!$A:$A,$A6) | AE6: 35 according to mcp.shapes.co ("35+ tools"), all read-only | AF6: Cannot be determined | AG6: Tool descriptions not published | AH6: Any changes: create or change an employee, book time off, answer a survey, carry out a review, upload or sign a document (Docs & eSign). Compensation: promised "compensation gaps" analysis but no salary tool in the list (possibly via employee fields - unconfirmed). Shapes AI functions (Vibe Views, Shapes Agents, Workflows). | AI6: None explicit; no recommendations on human confirmation (not needed, read-only) or on handling personal data in an AI chat. | AJ6: "Shapes is SOC2 certified and GDPR compliant so your people data stays protected, always"; "Your permissions carry over" / "No one sees more than they should". Privacy policy: AI features may use unnamed third-party LLM providers; data stored in Israel, EEA, UK, USA etc.; Shapes may train models on product usage data after removing personal data; customer data governed by a DPA and the "AI Modules Schedule". HR data received by the AI client goes to the AI provider - not mentioned in the MCP documentation. | AK6: "Connect in minutes. No engineering required."; the AI can answer about "attrition risk, headcount, and compensation gaps" | AL6: Read-only confirmed by the tool names (only list_, get_, aggregate_, search_, read_). Compensation analysis not confirmed by the tool list. | AM6: https://shapes.co/mcp https://mcp.shapes.co/ https://mcp.shapes.co/.well-known/oauth-protected-resource https://mcp.shapes.co/.well-known/oauth-authorization-server https://shapes.co/pricing https://shapes.co/privacy-policy https://claude.com/connectors/shapes https://getknit.dev/mcp-servers/shapes | AN6: Closed code, server returns 401 without sign-in, so tools/list is unavailable. The landing page gives http:// instead of https:// (probably a typo). Company: DreamTeam HR Apps Ltd. (d/b/a Shapes). Not to be confused with the third-party Knit wrapper with 25 writing actions.
A7: lucid | B7: Verified | C7: Manual analysis using Claude Opus 5.5 for verification and code analysis | D7: 2026-10-13; re-analysed 2026-10-22 (new commit in the repository) | E7: =((LEN(TRIM(I7))>0)*1+(LEN(TRIM(J7))>0)*1+(LEN(TRIM(K7))>0)*1+(LEN(TRIM(L7))>0)*1+(LEN(TRIM(M7))>0)*1+(LEN(TRIM(N7))>0)*1+(LEN(TRIM(O7))>0)*1+(LEN(TRIM(P7))>0)*1+(LEN(TRIM(Q7))>0)*1+(LEN(TRIM(R7))>0)*1+(LEN(TRIM(S7))>0)*1+(LEN(TRIM(T7))>0)*1+(LEN(TRIM(U7))>0)*1+(LEN(TRIM(V7))>0)*1+(LEN(TRIM(W7))>0)*1+(LEN(TRIM(X7))>0)*1+(LEN(TRIM(Y7))>0)*1+(LEN(TRIM(AA7))>0)*1+(LEN(TRIM(AB7))>0)*1+(LEN(TRIM(AC7))>0)*1+(LEN(TRIM(AE7))>0)*1+(LEN(TRIM(AF7))>0)*1+(LEN(TRIM(AG7))>0)*1+(LEN(TRIM(AH7))>0)*1+(LEN(TRIM(AI7))>0)*1+(LEN(TRIM(AJ7))>0)*1+(LEN(TRIM(AK7))>0)*1+(LEN(TRIM(AL7))>0)*1)/28 | F7: https://mcp.lucid.app/mcp | G7: https://github.com/lucidsoftware/lucid-mcp-server | H7: global | I7: https://github.com/lucidsoftware/lucid-mcp-server (skills and plugins only; the server code is closed) | J7: https://help.lucid.co/hc/en-us/articles/42578801807508-Integrate-Lucid-with-AI-tools-using-the-Lucid-MCP-server; https://community.lucid.co/product-questions-3/available-actions-with-the-lucid-mcp-server-13985; https://lucid.co/mcp-server | K7: No | L7: Not published | M7: f3827e4cd2d449463350cd0d725e35d6d2ecd082 (skills repository; server code not applicable) | N7: 2026-10-22 | O7: Not published | P7: Not published | Q7: No | R7: Server proprietary; skills/plugins repository MIT (c) 2026 Lucid Software, Inc. | S7: Freemium | T7: No separate fee; available on Free, Individual, Team and Enterprise plans, not for FedRAMP accounts | U7: Freemium | V7: Lucidchart/Lucidspark proprietary SaaS with a free plan; exact prices could not be checked (pricing page needs JavaScript; manual check: https://lucid.app/pricing/lucidchart) | W7: Plan-based SaaS; API key access for Team/Enterprise marked as premium | X7: Team/Enterprise: the administrator must enable MCP (Admin -> Security -> Feature controls / AI controls -> MCP access); enabling allows any AI client (cannot be limited to specific clients). The server sees all documents the user can access in their account, not other accounts. Reduced endpoints /readonly and /repositories. Not for FedRAMP. | Y7: Lucid account administrator; Lucid (plans, FedRAMP); user (choice of endpoint) | Z7: =COUNTIFS(Capabilities!$A:$A,$A7,Capabilities!$C:$C,"Yes")+COUNTIFS(Capabilities!$A:$A,$A7,Capabilities!$C:$C,"Partially") | AA7: 1) Different endpoints = different rights (/mcp/readonly, /mcp/repositories) instead of scopes. 2) Validation before action (lucid_validate_diagram_specification; creation tools require reading a reference resource first). 3) lucid_run_script: "Changes are atomic and time-limited". 4) lucid_submit_feedback sends feedback to Airfocus with user ID, account ID and client user agent. 5) Behaviour rules moved to skills outside the server ("Confirm before destructive actions, bulk changes, broad permission changes, or anonymous share links") - not enforced by the server. 6) Skill "visualizations" promotes Lucid over Mermaid/ASCII/Markdown tables. 7) Pass-through: no storage of documents, prompts or queries. | AB7: Non-standard | AC7: One service via three endpoints with different tool sets (full / read-only / repositories only), plus a separate layer of skills/plugins distributed outside the server. | AD7: =COUNTIF(Actions!$A:$A,$A7) | AE7: 35 in Composio (2026-10-12), 30 in Scalekit; combined list 40 names; only lucid_submit_feedback officially confirmed. The set changes over time. | AF7: Cannot be determined | AG7: Descriptions not published; catalogues call them "long" with "detailed usage rules" | AH7: Create data-linked diagrams that update automatically; export to Visio (PNG only); create diagrams from templates, delete tabs (unconfirmed); access documents outside the own account; administer the account and user rights. | AI7: Skill lucid: confirm deletion, bulk changes, permission changes and anonymous links; read the document before editing; do not invent IDs (instructions for the AI, not server checks). The Help Center gives no recommendations on human review. The API key is advertised for working without confirmations ("no runtime approval prompt"). | AJ7: "The server acts as a pass-through - it does not retain document content, user prompts, or queries. Your credentials are never shared outside your Lucid account"; "It cannot access documents owned or created by users outside your account"; feedback goes to Airfocus with user/account ID "only when the feedback tool is called"; AI clients are "Non-Lucid Applications" governed by the AI provider contract. | AK7: "Connect your AI tools to Lucid to intelligently search for files, create visuals, and share with your team"; "compatible with any MCP client"; the action list in the community post is called "exhaustive" | AL7: "Pass-through" cannot be verified (closed code). The read-only endpoint is described, but its exact tool set is not named. | AM7: https://github.com/lucidsoftware/lucid-mcp-server/tree/f3827e4cd2d449463350cd0d725e35d6d2ecd082 https://help.lucid.co/hc/en-us/articles/42578801807508-Integrate-Lucid-with-AI-tools-using-the-Lucid-MCP-server https://community.lucid.co/product-questions-3/available-actions-with-the-lucid-mcp-server-13985 https://composio.dev/toolkits/lucid_mcp/framework/hermes-agent.md https://www.scalekit.com/connectors/lucidmcp | AN7: The CSV link points to a repository without server code (skills and plugin configs only). Tool names come from two third-party catalogues whose lists differ (35 vs 30). OAuth metadata could not be checked (robots.txt).
A8: gocardless | B8: Verified | C8: Manual analysis using Claude Opus 5.5 for verification and code analysis | D8: 2026-10-13 | E8: =((LEN(TRIM(I8))>0)*1+(LEN(TRIM(J8))>0)*1+(LEN(TRIM(K8))>0)*1+(LEN(TRIM(L8))>0)*1+(LEN(TRIM(M8))>0)*1+(LEN(TRIM(N8))>0)*1+(LEN(TRIM(O8))>0)*1+(LEN(TRIM(P8))>0)*1+(LEN(TRIM(Q8))>0)*1+(LEN(TRIM(R8))>0)*1+(LEN(TRIM(S8))>0)*1+(LEN(TRIM(T8))>0)*1+(LEN(TRIM(U8))>0)*1+(LEN(TRIM(V8))>0)*1+(LEN(TRIM(W8))>0)*1+(LEN(TRIM(X8))>0)*1+(LEN(TRIM(Y8))>0)*1+(LEN(TRIM(AA8))>0)*1+(LEN(TRIM(AB8))>0)*1+(LEN(TRIM(AC8))>0)*1+(LEN(TRIM(AE8))>0)*1+(LEN(TRIM(AF8))>0)*1+(LEN(TRIM(AG8))>0)*1+(LEN(TRIM(AH8))>0)*1+(LEN(TRIM(AI8))>0)*1+(LEN(TRIM(AJ8))>0)*1+(LEN(TRIM(AK8))>0)*1+(LEN(TRIM(AL8))>0)*1)/28 | F8: https://mcp.gocardless.com/mcp | G8: https://developer.gocardless.com/developer-tools/mcp/ | H8: global | I8: Not published | J8: https://docs.gocardless.com/docs/developer-resources/mcp (CSV link redirects here); https://support.gocardless.com/hc/en-gb/articles/26830050176028-Use-AI-to-manage-your-account | K8: Unknown | L8: Not published | M8: Not applicable (closed code) | N8: Documentation snapshot 2026-10-13 | O8: Not published | P8: Not published | Q8: No | R8: Proprietary | S8: Free | T8: "The CLI, MCP and MCP Data are provided free of charge", but "GoCardless reserves the right to charge in the future" (terms 2.3) | U8: Paid | V8: Per transaction: Standard 1% + 20p (max £4), international 2% + 20p; Advanced 1.25% + 20p (max £5); Pro 1.4% + 20p (max £5.60); Custom by agreement; no subscription fee except add-ons (£50 and £150/month) | W8: Transaction fees for the payment service; MCP free | X8: Claude requires Pro, Max, Team or Enterprise (free AI plans "typically don't support MCPs"); on Team/Enterprise the Owner adds the connector first. Rights chosen by the user at sign-in (everything, read-only or specific actions); intersected with the user's dashboard role; bulk limits (e.g. max 25 payments at a time); access expires periodically. Live and Sandbox are separate connections. Rate limits not documented. | Y8: User (rights at sign-in), dashboard administrator (roles), GoCardless (limits, masking) | Z8: =COUNTIFS(Capabilities!$A:$A,$A8,Capabilities!$C:$C,"Yes")+COUNTIFS(Capabilities!$A:$A,$A8,Capabilities!$C:$C,"Partially") | AA8: According to the documentation (closed code): 1) Money-moving actions need explicit confirmation after a preview (mechanism not disclosed). 2) Masking of e-mail, phone, postcode, ID numbers before the AI sees them; bank details never passed. 3) Granular rights at sign-in (down to "refunds only") intersected with the user role. 4) Bulk limits (<= 25 payments per call). 5) All MCP actions logged in Events with source "App (GoCardless MCP)". 6) Separate Sandbox and Live connections and terms. 7) Access expires periodically; API tokens discouraged. | AB8: Standard | AC8: Two purposes in one server: integration help (no account access) and account management (after sign-in) | AD8: =COUNTIF(Actions!$A:$A,$A8) | AE8: 24 according to Composio (human-readable names; not officially confirmed). Support also mentions payment "retry", not in the catalogue. | AF8: Cannot be determined | AG8: Descriptions not published | AH8: Create customers and mandates directly (only payment links); manage account settings, users, webhooks; run Sandbox scenario simulators; see unmasked personal data and bank details; act outside the rights chosen at sign-in. | AI8: "Never share your API keys with your LLM"; use the sandbox during development; review generated code; give the AI only the necessary rights; test writing actions in Sandbox first; give the exact resource and amount and read the preview; check the AI provider's policy (free plans: "conversations may be used for AI training"); add "For any prompt that mentions GoCardless, use the GoCardless MCP" to prompts; agents without human review carry "extra risk" and the user is responsible for their actions. | AJ8: Masking of sensitive data, bank details never passed; log of all actions in Events. Terms: liability capped at £50 (9.5); processing personal data via MCP prohibited (4.1.5); the AI provider must use data only for the answer and delete it immediately (4.2.1, 4.2.4); the user is liable for breaches by the provider (4.3); no guarantee against "bias or hallucinations" (7.3); no guaranteed availability (2.4). | AK8: Two functions - "integration guidance and account management"; possibility to request a missing feature | AL8: Confirmation, masking, limits and log cannot be verified (closed code). Internal contradiction: the terms prohibit processing personal data via MCP, but the server returns customer data (masked). The requirement that the AI provider delete data immediately cannot be ensured by the user. | AM8: https://docs.gocardless.com/docs/developer-resources/mcp https://support.gocardless.com/hc/en-gb/articles/26830050176028-Use-AI-to-manage-your-account https://docs.gocardless.com/docs/developer-resources/mcp/terms https://docs.gocardless.com/docs/developer-resources/mcp/terms-sandbox https://mcp.gocardless.com/.well-known/oauth-protected-resource https://mcp.gocardless.com/.well-known/oauth-authorization-server https://composio.dev/toolkits/gocardless_mcp/framework/claude-cowork https://gocardless.com/pricing/ https://developer.gocardless.com/api-reference | AN8: CSV endpoint https://mcp.gocardless.com/mcp; docs give https://mcp.gocardless.com. The open-source gocardless-mcp by jmceleney on glama.ai is unofficial and not part of the analysis. Tool names in the catalogue are human-readable; real tools/list names may differ.
A9: airwallex | B9: Verified | C9: Manual analysis using Claude Opus 5.5 for verification and code analysis | D9: 2026-10-13 | E9: =((LEN(TRIM(I9))>0)*1+(LEN(TRIM(J9))>0)*1+(LEN(TRIM(K9))>0)*1+(LEN(TRIM(L9))>0)*1+(LEN(TRIM(M9))>0)*1+(LEN(TRIM(N9))>0)*1+(LEN(TRIM(O9))>0)*1+(LEN(TRIM(P9))>0)*1+(LEN(TRIM(Q9))>0)*1+(LEN(TRIM(R9))>0)*1+(LEN(TRIM(S9))>0)*1+(LEN(TRIM(T9))>0)*1+(LEN(TRIM(U9))>0)*1+(LEN(TRIM(V9))>0)*1+(LEN(TRIM(W9))>0)*1+(LEN(TRIM(X9))>0)*1+(LEN(TRIM(Y9))>0)*1+(LEN(TRIM(AA9))>0)*1+(LEN(TRIM(AB9))>0)*1+(LEN(TRIM(AC9))>0)*1+(LEN(TRIM(AE9))>0)*1+(LEN(TRIM(AF9))>0)*1+(LEN(TRIM(AG9))>0)*1+(LEN(TRIM(AH9))>0)*1+(LEN(TRIM(AI9))>0)*1+(LEN(TRIM(AJ9))>0)*1+(LEN(TRIM(AK9))>0)*1+(LEN(TRIM(AL9))>0)*1)/28 | F9: https://mcp.airwallex.com/mcp | G9: https://www.airwallex.com/docs/developer-tools/ai/agentos | H9: global | I9: Server closed; plugins and skills: https://github.com/airwallex/airwallex-marketplace | J9: https://www.airwallex.com/docs/developer-tools/ai/agentos (from CSV, incl. the .md version); https://www.airwallex.com/docs/developer-tools/ai/developer-connector.md | K9: No | L9: Not published | M9: 877551077786664d1cbeb32013443291c66e69e6 (skills repository; server not applicable) | N9: 2026-10-14 | O9: Not published | P9: Not published | Q9: No | R9: Server proprietary; skills/plugins Apache 2.0 | S9: Unknown | T9: No separate price for MCP given | U9: Paid | V9: EU plans: Explore €0 (with deposits/balance >= €10,000/month, otherwise €19/month), Grow €49/month, Accelerate custom; FX markup 0.5% (major currencies) / 1% (others); Core API included in Explore, fees may apply for additional access | W9: Monthly plan + FX markups for the financial platform | X9: OAuth to the production account with user-selected scopes ("grant only the OAuth scopes your use case needs"); no outgoing money operations (no write scopes for transfers/FX/payouts); Airwallex user rights and roles. Production only (sandbox is the separate Developer MCP). AgentOS skills are beta. Rate limits not documented. | Y9: Airwallex (scope set, money-out ban), user (scopes at sign-in) | Z9: =COUNTIFS(Capabilities!$A:$A,$A9,Capabilities!$C:$C,"Yes")+COUNTIFS(Capabilities!$A:$A,$A9,Capabilities!$C:$C,"Partially") | AA9: 1) Money-out ban at the level of rights: only read scopes for transfers and conversions ("AgentOS components do not initiate money-out actions"). 2) Writing tools annotated so that clients ask for confirmation (confirmation shown by the client). 3) Environment (production) declared in the server instructions. 4) Production only; sandbox is a separate server. 5) Rules in skills outside the server: never fabricate, stop and ask; name the environment and get explicit confirmation before irreversible operations; show the full payload before a write; "Do not provide financial advice"; CLI --dry-run -> confirm -> --confirm. 6) Feedback scope devx.feedback_write; skills tell the agent to offer feedback itself (with consent, no sensitive data). | AB9: Non-standard | AC9: Ecosystem of three separate servers by purpose and environment (AgentOS production / Developer sandbox / Docs) plus a common skills layer that works via MCP and CLI | AD9: =COUNTIF(Actions!$A:$A,$A9) | AE9: Exact number not published; reconstructed from OAuth scopes: 23 read and 12 write scopes (incl. feedback) + documentation search. The 12 tools in the Claude catalogue belong to the Developer MCP, not AgentOS. | AF9: Cannot be determined | AG9: Tool list not published | AH9: Transfers, payouts, currency exchange (dashboard only, "FX conversion: Airwallex Dashboard only"); get card number/CVV; delete a draft invoice, credit notes (CLI/dashboard only); work in the sandbox via AgentOS (needs the Developer MCP). | AI9: Turn off auto-approval modes ("Auto-Run", "Dangerously Skip Permissions"); confirm writes in the Airwallex web or mobile app; treat untrusted documents and web pages as prompt injection risk and review every tool call; do not paste API tokens; new chat for sensitive tasks; use a frontier model; install only trusted MCP servers alongside; do not add the agent to shared channels (Slack); grant only the necessary scopes. | AJ9: "AgentOS components do not initiate money-out actions" (confirmed by scopes). Writing tools annotated for confirmation. No privacy section in the MCP docs (link to Terms of Service). "Agent outputs are probabilistic". Logging of agent actions not described. | AK9: Tools so that agents "act on a production Airwallex account"; support for Claude Code, Claude Cowork, Cursor, Codex and others | AL9: "No money-out" confirmed by public OAuth metadata (no write scopes for transfers and FX). Annotations and instructions cannot be verified without signing in. | AM9: https://www.airwallex.com/docs/developer-tools/ai/agentos https://www.airwallex.com/docs/developer-tools/ai/agentos.md https://www.airwallex.com/docs/developer-tools/ai/developer-connector.md https://github.com/airwallex/airwallex-marketplace/tree/877551077786664d1cbeb32013443291c66e69e6 https://mcp.airwallex.com/.well-known/oauth-protected-resource/mcp https://mcp.airwallex.com/.well-known/oauth-authorization-server/mcp https://www.airwallex.com/de/pricing https://www.airwallex.com/docs/developer-tools/partner-connections/oauth-permissions https://claude.com/marketplace/connectors/airwallex | AN9: Tool list not published anywhere ("Discover tool names from your MCP client's tool list. Do not assume names"); actions reconstructed from the OAuth scopes. Meaning of pa_view not published (probably Payment Acceptance).
A10: braze | B10: Verified | C10: Manual analysis using Claude Opus 5.5 for verification and code analysis | D10: 2026-10-13 | E10: =((LEN(TRIM(I10))>0)*1+(LEN(TRIM(J10))>0)*1+(LEN(TRIM(K10))>0)*1+(LEN(TRIM(L10))>0)*1+(LEN(TRIM(M10))>0)*1+(LEN(TRIM(N10))>0)*1+(LEN(TRIM(O10))>0)*1+(LEN(TRIM(P10))>0)*1+(LEN(TRIM(Q10))>0)*1+(LEN(TRIM(R10))>0)*1+(LEN(TRIM(S10))>0)*1+(LEN(TRIM(T10))>0)*1+(LEN(TRIM(U10))>0)*1+(LEN(TRIM(V10))>0)*1+(LEN(TRIM(W10))>0)*1+(LEN(TRIM(X10))>0)*1+(LEN(TRIM(Y10))>0)*1+(LEN(TRIM(AA10))>0)*1+(LEN(TRIM(AB10))>0)*1+(LEN(TRIM(AC10))>0)*1+(LEN(TRIM(AE10))>0)*1+(LEN(TRIM(AF10))>0)*1+(LEN(TRIM(AG10))>0)*1+(LEN(TRIM(AH10))>0)*1+(LEN(TRIM(AI10))>0)*1+(LEN(TRIM(AJ10))>0)*1+(LEN(TRIM(AK10))>0)*1+(LEN(TRIM(AL10))>0)*1)/28 | F10: https://mcp.braze.com/mcp | G10: https://www.braze.com/docs/user_guide/brazeai/mcp_server | H10: global | I10: Remote server closed; deprecated local server only as PyPI package https://pypi.org/project/braze-mcp-server/ (no public repository found) | J10: https://www.braze.com/docs/user_guide/brazeai/mcp_server (from CSV); https://www.braze.com/docs/developer_guide/mcp_server/; setup, usage and available_api_functions pages | K10: No | L10: Not published | M10: Not applicable (closed code) | N10: Documentation snapshot 2026-10-13 | O10: Remote: not published; deprecated local: Python >= 3.12 | P10: Not published | Q10: No | R10: Remote proprietary; deprecated local package MIT | S10: Unknown | T10: No price given; available to Braze customers | U10: Paid | V10: Proprietary enterprise platform; no public prices (by contract) | W10: Enterprise contract | X10: Permission "Use MCP Server" off by default, granted per workspace; the company administrator must enable MCP OAuth and approve the client's redirect URI; only allowlisted AI clients (Claude, ChatGPT, Cursor, OpenAI Codex, Claude Code, VS Code); agent rights = dashboard rights, checked per request; does not work with IP Allowlisting; asterisked tools need the campaigns API beta program. Rate limits not documented. | Y10: Company administrator in Braze (OAuth, permissions, mass token revocation); Braze (client allowlist, beta program) | Z10: =COUNTIFS(Capabilities!$A:$A,$A10,Capabilities!$C:$C,"Yes")+COUNTIFS(Capabilities!$A:$A,$A10,Capabilities!$C:$C,"Partially") | AA10: 1) PII excluded by design (no user-level tools; only aggregates and configuration). 2) Dashboard rights inherited and checked per request; deactivated users lose access immediately. 3) Multi-level access: "Use MCP Server" permission (off by default) + OAuth enabled by admin + redirect URI approval + client allowlist. 4) Batch limits (catalogues <= 50 items) and pagination. 5) Campaign edits recorded under the user's name in the change history. 6) Nested agent: send_operator_prompt hands tasks to BrazeAI Operator in the background. 7) Beta gating (15 campaign tools, 3 segment tools). 8) No server-side confirmation: "Braze receives and executes the tool call as the AI model sends it". | AB10: Standard | AC10: Standard, but with a nested vendor agent (BrazeAI Operator); two regional endpoints (US mcp.braze.com, EU mcp.braze.eu), each works with any cluster | AD10: =COUNTIF(Actions!$A:$A,$A10) | AE10: 71 according to the documentation: 37 reading, 34 changing; 18 require the beta program | AF10: Cannot be determined | AG10: Exact descriptions and schemas not published; with 71 tools probably considerable | AH10: User data (PII): profiles, export, deletion; Canvas is read-only; send messages directly (Messaging API); drag-and-drop templates; delete templates and content blocks; administration (users, rights, API keys, company settings); without beta: create/edit campaigns and segments. | AI10: Do not use auto-mode in the AI client; "review any AI-proposed action before implementing it"; "Compare high-impact recommendations against source data"; name the workspace explicitly in every request (production vs staging), otherwise the agent may "choose an unexpected workspace"; specify dates and metrics; ask the agent which tools it used. | AJ10: "non-PII Braze data" / "Tools that expose user-level PII are not available"; "An agent can never exceed your own access"; campaign edits visible in the change history; "Braze does not see your original natural-language prompt"; disclaimer: Braze "not liable for instructions generated by, or responses conveyed through, third-party MCP clients"; privacy policy: Braze is processor for customer data, "We maintain human oversight and do not make decisions based solely on automated processing" (Braze's own AI); no overall MCP activity log described. | AK10: "a secure remote connection that lets AI tools like Claude and Cursor access non-PII Braze data"; one connector for all accessible workspaces | AL10: "non-PII" consistent with the tool list (no user export, only aggregates and configuration), but catalogues, media and content blocks can contain any data the customer uploaded - not discussed. | AM10: https://www.braze.com/docs/user_guide/brazeai/mcp_server https://www.braze.com/docs/developer_guide/mcp_server/ https://www.braze.com/docs/user_guide/brazeai/mcp_server/setup/ https://www.braze.com/docs/user_guide/brazeai/mcp_server/usage/ https://braze.com/docs/developer_guide/mcp_server/available_api_functions/ https://mcp.braze.com/.well-known/oauth-protected-resource https://pypi.org/project/braze-mcp-server/ https://www.braze.com/company/legal/privacy | AN10: Tool list from the official documentation (names and short descriptions); exact tools/list not verifiable without signing in. Local server (PyPI 1.2.0, 14.05.2026) deprecated and smaller than the remote one.
A11: clickup | B11: Verified | C11: Manual analysis using Claude Opus 5.5 for verification and code analysis | D11: 2026-10-14 | E11: =((LEN(TRIM(I11))>0)*1+(LEN(TRIM(J11))>0)*1+(LEN(TRIM(K11))>0)*1+(LEN(TRIM(L11))>0)*1+(LEN(TRIM(M11))>0)*1+(LEN(TRIM(N11))>0)*1+(LEN(TRIM(O11))>0)*1+(LEN(TRIM(P11))>0)*1+(LEN(TRIM(Q11))>0)*1+(LEN(TRIM(R11))>0)*1+(LEN(TRIM(S11))>0)*1+(LEN(TRIM(T11))>0)*1+(LEN(TRIM(U11))>0)*1+(LEN(TRIM(V11))>0)*1+(LEN(TRIM(W11))>0)*1+(LEN(TRIM(X11))>0)*1+(LEN(TRIM(Y11))>0)*1+(LEN(TRIM(AA11))>0)*1+(LEN(TRIM(AB11))>0)*1+(LEN(TRIM(AC11))>0)*1+(LEN(TRIM(AE11))>0)*1+(LEN(TRIM(AF11))>0)*1+(LEN(TRIM(AG11))>0)*1+(LEN(TRIM(AH11))>0)*1+(LEN(TRIM(AI11))>0)*1+(LEN(TRIM(AJ11))>0)*1+(LEN(TRIM(AK11))>0)*1+(LEN(TRIM(AL11))>0)*1)/28 | F11: https://mcp.clickup.com/mcp | G11: https://developer.clickup.com/docs/connect-an-ai-assistant-to-clickups-mcp-server | H11: global | I11: Not published | J11: https://developer.clickup.com/docs/connect-an-ai-assistant-to-clickups-mcp-server (from CSV); https://developer.clickup.com/docs/mcp-tools | K11: Unknown | L11: Not published | M11: Not applicable (closed code) | N11: Documentation snapshot 2026-10-14 | O11: Not published | P11: Not published | Q11: No | R11: Proprietary | S11: Free | T11: Available on all plans, no separate fee; MCP does not consume AI credits | U11: Freemium | V11: Free Forever $0; Unlimited $7 (annual) / $10 (monthly) per user; Business $12/$19; Enterprise on request. The same page also shows Core $9, Business $17, Max $100 (contradictory). Everything AI add-on $28 per user/month. | W11: Per-user plans; MCP call limits depend on the plan and the Everything AI add-on | X11: Calls per rolling 24 h without Everything AI: Free 100, Core/Unlimited 300, Business 1,000, Business Plus 2,500, Enterprise 5,000, Enterprise Plus 25,000 - per workspace and per AI client separately; initialize and tools/list not counted; with the add-on - public API limits; RATE_LIMIT_EXCEEDED with retryAfter, cannot be reset. OAuth only (no personal API keys); rights = the user's ClickUp rights; AI fair use policy. | Y11: ClickUp (plans, limits, fair use), workspace administrator (user rights) | Z11: =COUNTIFS(Capabilities!$A:$A,$A11,Capabilities!$C:$C,"Yes")+COUNTIFS(Capabilities!$A:$A,$A11,Capabilities!$C:$C,"Partially") | AA11: 1) Daily call limits per AI client and workspace (plan-dependent). 2) Deletion restricted "as a safety measure for now" - but the tool list contains "Delete task" (the assistant "may confirm") - contradiction. 3) The user's ClickUp rights are inherited. 4) Server-side confirmation and agent action log not described. 5) Connected Search not available via MCP. | AB11: Standard | AC11: Flat set of tools | AD11: =COUNTIF(Actions!$A:$A,$A11) | AE11: 48 according to the Supported Tools page (human-readable names) | AF11: Cannot be determined | AG11: Descriptions not published | AH11: Delete lists, folders, spaces, documents, comments (only tasks); manage members and rights; automations; goals, dashboards, whiteboards; Connected Search across external apps. | AI11: No explicit recommendations on human confirmation (except "may confirm" before deleting a task). | AJ11: Only links to security, privacy and AI fair use policies; no specific promises about data passed to the AI. | AK11: "available on all plans"; limits "may change", "future restrictions" possible | AL11: The "no deletion" statement contradicts the tool "Delete task". | AM11: https://developer.clickup.com/docs/connect-an-ai-assistant-to-clickups-mcp-server https://developer.clickup.com/docs/mcp-tools https://mcp.clickup.com/.well-known/oauth-protected-resource https://mcp.clickup.com/.well-known/oauth-authorization-server https://clickup.com/pricing https://developer.clickup.com/llms.txt | AN11: Endpoint https://mcp.clickup.com/mcp; data from https://api.clickup.com (resource_server_origin). Tool names are human-readable (docs); exact tools/list not available without sign-in.
A12: motion | B12: Verified | C12: Manual analysis using Claude Opus 5.5 for verification and code analysis | D12: 2026-10-14; re-analysed 2026-10-23 (new commit in the repository) | E12: =((LEN(TRIM(I12))>0)*1+(LEN(TRIM(J12))>0)*1+(LEN(TRIM(K12))>0)*1+(LEN(TRIM(L12))>0)*1+(LEN(TRIM(M12))>0)*1+(LEN(TRIM(N12))>0)*1+(LEN(TRIM(O12))>0)*1+(LEN(TRIM(P12))>0)*1+(LEN(TRIM(Q12))>0)*1+(LEN(TRIM(R12))>0)*1+(LEN(TRIM(S12))>0)*1+(LEN(TRIM(T12))>0)*1+(LEN(TRIM(U12))>0)*1+(LEN(TRIM(V12))>0)*1+(LEN(TRIM(W12))>0)*1+(LEN(TRIM(X12))>0)*1+(LEN(TRIM(Y12))>0)*1+(LEN(TRIM(AA12))>0)*1+(LEN(TRIM(AB12))>0)*1+(LEN(TRIM(AC12))>0)*1+(LEN(TRIM(AE12))>0)*1+(LEN(TRIM(AF12))>0)*1+(LEN(TRIM(AG12))>0)*1+(LEN(TRIM(AH12))>0)*1+(LEN(TRIM(AI12))>0)*1+(LEN(TRIM(AJ12))>0)*1+(LEN(TRIM(AK12))>0)*1+(LEN(TRIM(AL12))>0)*1)/28 | F12: https://mcp.motion.dev/mcp | G12: https://motion.dev/docs/ai-kit | H12: global | I12: Server closed; skills/plugin/installer: https://github.com/motiondivision/ai-kit | J12: https://motion.dev/docs/ai-kit (from CSV); https://mcp.motion.dev/mcp (server page); https://motion.dev/plus | K12: No | L12: 2025-06-18 (stated by the server) | M12: 0ebeb5313a069986376430f665415252e223d1d4 (ai-kit repository; server not applicable) | N12: 2026-10-23 | O12: Not published | P12: Not published | Q12: No | R12: Server proprietary; ai-kit MIT | S12: Freemium | T12: Free server: "Documentation search is free. No token, account or configuration is required." Motion+ (separate endpoint /plus): one-time purchase per developer ("Pay once", "Yours forever"; amount did not load); annual Pro add-on (AI agent Ultramotion) | U12: Open source | V12: Motion library free (MIT) | W12: Free documentation search; one-time Motion+ license; annual Pro add-on | X12: Paid features need Motion+ sign-in; the performance audit only profiles a "running local site" | Y12: Motion (license tiers) | Z12: =COUNTIFS(Capabilities!$A:$A,$A12,Capabilities!$C:$C,"Yes")+COUNTIFS(Capabilities!$A:$A,$A12,Capabilities!$C:$C,"Partially") | AA12: 1) Monetisation via tool responses: "the rest is tiered, and the tools say so when you reach them" - the free tool tells the agent about paid features. 2) Two servers by access level (free / plus). 3) The performance evaluation methodology (MotionScore) is defined and changed on the server side and delivered at call time. 4) Behaviour rules in skills. | AB12: Non-standard | AC12: Two servers (free / plus) plus skills and a reviewer agent (plugins/motion/agents/motion-reviewer.md) in a separate repository | AD12: =COUNTIF(Actions!$A:$A,$A12) | AE12: Free server: 1 (search-motion-docs). Plus: not published (at least 4 groups: audit, example source code, springs, transition editor) | AF12: Cannot be determined (minimal with one tool) | AG12: Description not published | AH12: Without Motion+: generate springs, run the audit, get example and Motion UI source code; the agent cannot buy a license. | AI12: None | AJ12: Data processing and telemetry not described; the Motion+ audit analyses the user's project source code - what is sent to the server is not described. | AK12: "Hand-written advice by the creator of Motion"; "Nothing gets pasted into chat" (about sign-in) | AL12: Cannot be compared (closed code, no governance statements) | AM12: https://motion.dev/docs/ai-kit https://mcp.motion.dev/mcp https://github.com/motiondivision/ai-kit/tree/0ebeb5313a069986376430f665415252e223d1d4 https://motion.dev/plus | AN12: Not the Motion calendar (usemotion.com). Endpoints: free https://mcp.motion.dev (CSV: /mcp), paid https://mcp.motion.dev/plus. Direct requests from our environment were blocked by the network policy (the CSV records HTTP 200 without sign-in).
A13: quo | B13: Verified | C13: Manual analysis using Claude Opus 5.5 for verification and code analysis | D13: 2026-10-14 | E13: =((LEN(TRIM(I13))>0)*1+(LEN(TRIM(J13))>0)*1+(LEN(TRIM(K13))>0)*1+(LEN(TRIM(L13))>0)*1+(LEN(TRIM(M13))>0)*1+(LEN(TRIM(N13))>0)*1+(LEN(TRIM(O13))>0)*1+(LEN(TRIM(P13))>0)*1+(LEN(TRIM(Q13))>0)*1+(LEN(TRIM(R13))>0)*1+(LEN(TRIM(S13))>0)*1+(LEN(TRIM(T13))>0)*1+(LEN(TRIM(U13))>0)*1+(LEN(TRIM(V13))>0)*1+(LEN(TRIM(W13))>0)*1+(LEN(TRIM(X13))>0)*1+(LEN(TRIM(Y13))>0)*1+(LEN(TRIM(AA13))>0)*1+(LEN(TRIM(AB13))>0)*1+(LEN(TRIM(AC13))>0)*1+(LEN(TRIM(AE13))>0)*1+(LEN(TRIM(AF13))>0)*1+(LEN(TRIM(AG13))>0)*1+(LEN(TRIM(AH13))>0)*1+(LEN(TRIM(AI13))>0)*1+(LEN(TRIM(AJ13))>0)*1+(LEN(TRIM(AK13))>0)*1+(LEN(TRIM(AL13))>0)*1)/28 | F13: https://mcp.quo.com/mcp | G13: https://support.quo.com/core-concepts/integrations/mcp | H13: global | I13: Not published | J13: https://support.quo.com/core-concepts/integrations/mcp (from CSV); https://claude.com/connectors/quo | K13: Unknown | L13: Not published | M13: Not applicable (closed code) | N13: Documentation snapshot 2026-10-14 | O13: Not published | P13: Not published | Q13: No | R13: Proprietary | S13: Free | T13: "ChatGPT / Claude MCP" included in all plans at no extra charge; sending SMS via the AI assistant needs pre-paid credits | U13: Paid | V13: Starter $19/$15, Business $33/$23, Scale $47/$35 per user/month (monthly/annual); automation credits (1,000 free = 10 Sona AI agent calls; packages $25-$199/month); automated SMS via API $0.01 per segment | W13: Per-user plans + credits for automation and SMS | X13: Clients: Claude all users, ChatGPT Plus and Pro, Grok users. SMS only with pre-paid credits. Transcripts only on numbers where enabled. | Y13: Quo (plans, credits) | Z13: =COUNTIFS(Capabilities!$A:$A,$A13,Capabilities!$C:$C,"Yes")+COUNTIFS(Capabilities!$A:$A,$A13,Capabilities!$C:$C,"Partially") | AA13: 1) Pre-paid credits limit SMS sending by the agent. 2) OAuth scopes broader than the documentation (write:calls, read:agents, write:agents) - needs checking. 3) Confirmation before sending, bulk limits and logging not described. | AB13: Standard | AC13: According to the available information | AD13: =COUNTIF(Actions!$A:$A,$A13) | AE13: Not published; 6 capability groups in the docs (summaries, sending SMS, messages/inboxes, calls/transcripts, contacts, missed calls); scopes also point to call writing and AI agents | AF13: Cannot be determined | AG13: Tool list not published | AH13: Make calls (not stated in docs, although write:calls exists); manage numbers, users, billing; send SMS without credits. | AI13: None; nothing about confirming messages before sending. | AJ13: Not described in the MCP docs (link to the privacy policy). The agent has access to customer conversations and call transcripts (third-party personal data). | AK13: "Surface call insights and missed opportunities" | AL13: OAuth scopes reveal more capabilities (calls, AI agents) than the documentation describes. | AM13: https://support.quo.com/core-concepts/integrations/mcp https://claude.com/connectors/quo https://mcp.quo.com/.well-known/oauth-protected-resource https://mcp.quo.com/.well-known/oauth-authorization-server https://www.quo.com/pricing https://quo.com/privacy https://quo.com/blog/next-chapter/ | AN13: Quo = formerly OpenPhone. Official connector for Claude, ChatGPT, Grok. Actions reconstructed from documentation capability groups and OAuth scopes.
